Workbook

Sheet Sales_RAW(BEFORE)
A1: SALES REPORT - system export (DO NOT TOUCH!!!)
A4: transaction id | B4: date | C4: Delivery Date | D4: Product Code | E4: Product Name | F4: category | G4: Quantity | H4: Unit Price | I4: Discount % | J4: Total | K4: Currency | L4: Employee ID | M4: Sales Rep | N4: Region | O4: City | P4: Customer | Q4: Tax ID | R4: CUSTOMER EMAIL | S4: Phone | T4: Address | U4: ZIP Code | V4: country | W4: Payment Method | X4: Status | Y4: Payment Status | Z4: Invoice No. | AA4: Sales Channel | AB4: Quarter | AC4: Month | AD4: Year | AE4: Payment Terms | AF4: Days Overdue | AG4: VAT | AH4: VAT Amount | AI4: Amount incl. VAT | AJ4: Shipping Cost | AK4: Courier | AL4: tracking no. | AM4: WEIGHT (KG) | AN4: Warehouse | AO4: Stock | AP4: Customer Rating | AQ4: COMMENT | AR4: Returned? | AS4: return reason | AT4: Margin | AU4: Rep Commission | AV4: Customer Full Name | AW4: Contact Person | AX4: NOTES
A5: TR-2025001 | B5: 09.09.2025. | C5: 23-Sep-25 | D5: P33 | E5: Printer X 33 | F5: Office | G5: 7 | H5: 129.06 USD | I5: 10% | J5: 903.42 | K5: $ | L5: E016 | M5: chris anderson | N5: East | O5: houston | P5: wayne llc | Q5: EIN: 388875967 | R5: daniel.gmail.com | S5: (536) 760-6300 | T5: 344 Davis Street | U5: 63212 | V5: US | W5: credit card | X5: DELIVERED | Y5: Paid | Z5: INV/2025/0001 | AA5: Online | AB5: 1st quarter | AC5: 9 | AD5: 2025 | AE5: immediate | AG5: 0.08 | AJ5: 15,21 | AK5: DHL | AL5: 1Z806032141 | AM5: 23.5 kg | AN5: wh b | AO5: 76 | AP5: 3 | AR5: 1 | AS5: doesn't fit | AU5: 27.1 | AV5: Daniel Davis | AW5: Daniel Davis | AX5: duplicate?
A6: TR-2025002 | B6: 24.08.2025 | C6: 31-Aug-25 | D6: P-052 | F6: Furniture | G6: 2 | H6: 1467.86 | I6: 0.1 | J6: - | K6: usd | L6: e-023 | M6: laura anderson | N6: North | O6: New Yrok | P6: Wayne inc | Q6: 790161495 | R6: john.company.com | S6: +1 836 781 3186 | T6: 276 Johnson St. | U6: 89566 | V6: U.S. | W6: Cash | X6: Cancelled | Y6: Partial | Z6: INV/2025/0002 | AA6: Phone | AB6: Q1 | AC6: Aug | AD6: 2025 | AE6: Net 60 | AF6: 10 | AG6: 8% | AJ6: 14.48 | AK6: ups | AL6: FX515375252 | AM6: 6,4 | AN6: Warehouse A | AO6: 72 | AP6: 5 | AQ6: late delivery!! | AR6: NO | AS6: doesn't fit | AT6: 15 % | AU6: $88.07 | AV6: John Williams | AW6: same
A7: TR-2025003 | B7: 07-Apr-26 | C7: 13.04.2026 | D7: P-032 | E7: Cable Basic 32 | F7: software | G7: 20 kom. | H7: USD 1,480 | J7: 29595.40 | K7: USD | L7: EMP22 | M7: N/A | N7: South | O7: Huston | P7: Umbrella inc | Q7: 943040526 | R7: emma.company.com | S7: 949.620.8386 | T7: 771 Williams Ave | U7: null | V7: US | W7: credit card | X7: Cancelled | Y7: Partial | Z7: INV/2026/0003 | AA7: Store | AB7: 1st quarter | AC7: April | AD7: 2026 | AE7: Net 60 | AF7: 51 | AG7: 0.08 | AJ7: 24.16 | AK7: Fed Ex | AL7: DH273577842 | AM7: 24,37 | AN7: WH-A | AO7: 231 | AQ7: OK | AR7: NO | AS7: doesn't fit | AT7: 0,18 | AU7: - | AV7: Emma Williams | AW7: same
A8: TR-2025004 | B8: 28.01.2026 | C8: 02/05/2026 | D8: P48 | E8: LICENSE PLUS 48 | F8: software | G8: 34 kom. | H8: $471.22 | I8: 5% | J8: #N/A | K8: USD | L8: E014 | M8: SOPHIA BROWN | N8: west | O8: Huston | P8: initech inc | Q8: EIN: 986261507 | R8: sarah.gmail.com | S8: (240) 201-3058 | T8: 642 Jones Blvd | U8: 92564 | V8: USA | W8: Credit Card | X8: Processing | Y8: YES | Z8: INV/2026/0004 | AA8: online | AB8: q1 | AC8: January | AD8: 2026 | AE8: 15 | AF8: null | AG8: 0.08 | AJ8: $49.82 | AK8: USPS | AL8: 1Z610354022 | AM8: 16.5 kg | AN8: Warehouse B | AO8: #N/A | AP8: excellent | AR8: Yes | AV8: Sarah Davis | AW8: Sarah | AX8: urgent
A9: TR-2025005 | B9: 2026-06-01 | C9: 2026-06-09 | D9: P1 | E9: DESK X 1 | F9: #N/A | G9: 14 | H9: null | I9: 0.1 | K9: usd | L9: E010 | N9: South | O9: NYC | P9: initech inc | Q9: EIN: 134245587 | R9: laura.company.com | S9: +1 373 311 1047 | T9: 431 Johnson St. | U9: 50824 | V9: United States | W9: Wire Transfer | X9: Delivered | Y9: Paid | Z9: INV/2026/0005 | AA9: Phone | AB9: q1 | AC9: June | AD9: '26 | AE9: immediate | AF9: 24 | AG9: 8 | AJ9: USD 2 | AK9: USPS | AL9: FX143647055 | AM9: 11.33 | AN9: Warehouse B | AO9: 99 | AP9: 5/5 | AQ9: late delivery!! | AR9: Yes | AS9: damaged | AT9: 15 % | AU9: - | AV9: Laura Brown | AW9: Laura Brown
A10: TR-2025006 | B10: 20-Apr-25 | C10: 04-May-25 | D10: P-053 | E10: monitor basic 53 | F10: Equipment | G10: 30 kom | H10: 553.22 USD | I10: 10% | J10: N/A | K10: usd | L10: E008 | M10: #N/A | N10: North | O10: Houston | P10: vortex inc | Q10: 862110984 | R10: chris.gmail.com | S10: +1 965 751 2985 | T10: 581 Jones Ave | U10: 34299 | V10: US | W10: Wire Transfer | X10: delivered | Y10: paid | Z10: INV/2025/0006 | AA10: Web | AB10: q1 | AC10: 4 | AD10: 2025 | AE10: 15 | AF10: - | AG10: 0,08 | AJ10: 25,37 | AK10: FedEx | AL10: DH598125683 | AM10: 29.73 | AN10: wh b | AO10: 468 | AP10: 5 | AQ10: all good | AR10: No | AT10: 0,18 | AU10: 497,90 | AV10: Chris Davis | AW10: same | AX10: VIP customer
A11: TR-2025118 | B11: 06/14/2026 | C11: 20-Jun-26 | D11: P_004 | E11: printer plus 4 | F11: null | G11: 7 kom. | H11: 364.79 | I11: 10 | J11: N/A | K11: usd | L11: E015 | M11: Sarah Jones | N11: South | O11: houston | P11: Stark Inc. | Q11: EIN: 986739414 | R11: sophia.gmail.com | S11: 348.471.3029 | T11: 450 Brown St. | U11: 58661 | V11: USA | W11: credit card | X11: delivered | Y11: Paid | Z11: INV/2026/0118 | AA11: Online | AB11: Q3 | AC11: Jun | AD11: 2026 | AE11: 15 | AF11: 34 | AG11: 8% | AJ11: 40.91 | AK11: DHL | AL11: 1Z412227285 | AM11: 22,73 | AN11: Warehouse C | AO11: 56 | AP11: excellent | AR11: NO | AS11: damaged | AT11: 15 % | AU11: USD 77 | AV11: Sophia Johnson | AX11: check price
A12: TR-2025007 | B12: 07.01.2025 | C12: 01/13/2025 | D12: p039 | E12: Cable Plus 39 | F12: SOFTWARE | G12: 39 kom | H12: 601.47 | I12: 5% | J12: USD 23,457 | K12: USD | L12: E009 | M12: OLIVIA WILSON | N12: North | O12: new york | P12: Initech INC | Q12: EIN: 430278432 | R12: emma.gmail.com | S12: 859.401.7401 | T12: 415 Brown Street | U12: 57906 | V12: usa | W12: Credit Card | X12: Delivered | Y12: Partial | Z12: INV/2025/0007 | AA12: online | AB12: 1st quarter | AC12: January | AD12: 2025 | AE12: 15 | AF12: N/A | AG12: 8 | AJ12: 4,45 | AK12: USPS | AL12: DH284346077 | AM12: 4.46 | AN12: Warehouse A | AO12: 196 | AP12: 4 | AQ12: late delivery!! | AR12: NO | AU12: #N/A | AV12: EMMA ANDERSON | AW12: same | AX12: urgent
A13: TR-2025008 | B13: 20-Jul-25 | C13: 2025-07-29 | D13: P-040 | E13: null | F13: Software | G13: 31 kom. | H13: 98,06 | I13: 5% | J13: 3039.86 | K13: USD | L13: EMP13 | M13: Robert Williams | N13: west | O13: Miami | P13: GLOBEX INC. | Q13: EIN: 579768106 | R13: michael.gmail.com | S13: 574.293.8241 | T13: 523 Smith Street | U13: 84419 | V13: United States | W13: PayPal | X13: DELIVERED | Y13: Paid | Z13: INV/2025/0008 | AA13: Online | AB13: Q3 | AC13: July | AD13: '25 | AE13: 15 | AF13: 3 | AG13: 8% | AJ13: USD 10 | AK13: Fed Ex | AL13: DH946518213 | AM13: 25,01 | AN13: Warehouse B | AO13: 81 | AP13: 5 | AQ13: complaint | AR13: yes | AT13: 0.3 | AU13: 91,20 | AV13: Michael Anderson | AW13: same | AX13: check price
A14: TR-2025009 | B14: 23-Jul-25 | C14: 07/26/2025 | D14: P_024 | E14: CHAIR PLUS 24 | F14: Electronics | G14: 26 kom. | H14: 95.7 | I14: 0.1 | J14: USD 2,488 | K14: EUR | L14: e-002 | N14: East | O14: los angeles | P14: Wayne inc | Q14: 812640864 | R14: N/A | S14: (497) 830-8081 | T14: 628 Smith Street | U14: - | V14: United States | W14: Credit Card | X14: DELIVERED | Y14: Unpaid | Z14: INV/2025/0009 | AA14: online | AB14: q1 | AC14: July | AD14: '25 | AE14: Net 60 | AF14: - | AG14: 8 | AJ14: 7.93 | AK14: Fed Ex | AL14: DH260323700 | AM14: 4,43 | AN14: Warehouse B | AO14: 205 | AP14: 1 | AR14: 0 | AS14: doesn't fit | AT14: 0.3 | AU14: 74,65 | AV14: Michael Jones | AW14: same | AX14: urgent
A15: TR-2025010 | B15: 2025-02-15 | C15: null | D15: P-058 | E15: Laptop Pro 58 | F15: Furniture | G15: 35 | H15: $711.00 | I15: 0 | J15: 24885.00 USD | K15: EUR | L15: E001 | M15: #N/A | N15: South | O15: new york | P15: Globex INC | Q15: EIN: 460257622 | R15: john.company.com | S15: (851) 767-8144 | T15: 902 Taylor Street | U15: 23252 | V15: US | W15: PayPal | X15: delivered | Y15: paid | Z15: INV/2025/0010 | AA15: Store | AB15: q1 | AC15: February | AD15: 2025 | AE15: 15 | AF15: 48 | AG15: 8 | AJ15: 23,61 | AK15: FedEx | AL15: FX878058375 | AM15: 26.6 kg | AN15: Warehouse C | AO15: 299 | AP15: 3 | AQ15: all good | AR15: No | AT15: 25% | AU15: 746.55 | AV15: john davis | AW15: John Davis
A16: TR-2025011 | B16: 02/13/2025 | C16: 17.02.2025. | D16: P-009 | E16: Chair Plus 9 | F16: - | G16: 5 kom. | H16: 813.33 | I16: 5% | J16: 4066.65 USD | K16: $ | L16: EMP23 | M16: Laura Anderson | N16: North | O16: seattle | P16: Acme Ltd. | Q16: EIN: 640883830 | R16: emma.yahoo.com | S16: 555.680.1788 | T16: 580 Brown Street | U16: 76306 | V16: US | W16: Wire Transfer | X16: Delivered | Y16: YES | Z16: INV/2025/0011 | AA16: Web | AB16: 1st quarter | AC16: 2 | AD16: 2025 | AE16: Net 60 | AF16: N/A | AG16: 8 | AJ16: 29.63 USD | AK16: DHL | AL16: 1Z404652501 | AM16: 24.48 | AN16: Warehouse A | AO16: 480 | AP16: 2 | AQ16: OK | AR16: 1 | AS16: doesn't fit | AT16: 25% | AU16: 122 | AV16: EMMA SMITH | AW16: Emma Smith | AX16: VIP customer
A17: TR-2025012 | B17: 26.01.2025. | C17: 29-Jan-25 | D17: P-057 | E17: keyboard x 57 | F17: Equipment | G17: 14 | H17: 741.71 USD | I17: 0 | J17: 10383,94 | K17: usd | L17: E021 | M17: #N/A | N17: West | O17: chicago | P17: Umbrella Ltd. | Q17: 987473445 | R17: david.company.com | S17: (453) 940-6350 | T17: 265 Johnson St. | U17: 87232 | V17: usa | W17: credit card | X17: delivered | Y17: Unpaid | Z17: INV/2025/0012 | AA17: Store | AB17: Q2 | AC17: January | AD17: 2025 | AE17: Net 30 | AF17: 81 | AG17: 0.08 | AJ17: USD 10 | AK17: FedEx | AL17: FX949334392 | AM17: 6.8 kg | AN17: wh b | AO17: 11 | AP17: excellent | AR17: 0 | AU17: 311.52 | AV17: David Jones | AW17: same | AX17: urgent
A18: TR-2025013 | B18: 10-Apr-26 | C18: 20260422 | D18: P42 | E18: Desk Max 42 | F18: Electronics | G18: 21 | H18: USD 158 | I18: 10% | J18: N/A | K18: usd | L18: e-004 | M18: #N/A | N18: NORTH | O18: Houston | P18: Umbrella INC | Q18: EIN: 896834466 | R18: david.gmail.com | S18: +1 981 325 6824 | T18: 392 Davis Street | U18: 02744 | V18: usa | W18: PayPal | X18: Pending | Y18: NO | Z18: INV/2026/0013 | AA18: Store | AB18: Q3 | AC18: April | AD18: 2026 | AE18: 15 | AF18: 38 | AG18: 0,08 | AJ18: USD 50 | AK18: Fed Ex | AL18: 1Z933875961 | AM18: 5,88 | AN18: Warehouse C | AO18: 369 | AP18: 3 | AQ18: late delivery!! | AR18: 0 | AS18: wrong item | AU18: $99.58 | AV18: David Johnson | AW18: same | AX18: check price
A19: TR-2025014 | B19: 09/17/2025 | C19: 20250921 | D19: P-046 | E19: - | F19: Equipment | G19: 12 | H19: 549,42 | I19: 0 | K19: usd | L19: E013 | M19: Robert Williams | N19: South | O19: Huston | P19: Vortex inc | Q19: 280294956 | R19: laura.company.com | S19: 743.280.8185 | T19: 904 Johnson Street | U19: 35667 | V19: US | W19: Wire Transfer | X19: Cancelled | Y19: YES | Z19: INV/2025/0014 | AA19: Online | AB19: Q2 | AC19: September | AD19: 2025 | AE19: immediate | AF19: 31 | AG19: 8% | AJ19: $8.02 | AK19: DHL | AL19: FX814361021 | AM19: 12,83 | AN19: Warehouse A | AO19: 92 | AP19: 1 | AT19: 0.3 | AU19: 197.79 USD | AV19: Laura Smith | AW19: Laura Smith | AX19: urgent
A20: TR-2025015 | B20: 10.05.2025. | C20: 2025-05-19 | D20: P46 | E20: Chair Basic 46 | F20: Equipment | G20: 7 kom | H20: 549,42 | I20: 5% | J20: 3845.94 | K20: $ | L20: EMP14 | M20: null | N20: west | O20: Chicago | P20: Initech LLC | Q20: 753571200 | R20: sophia.company.com | S20: 417.240.8501 | T20: 781 Williams Street | U20: 87981 | V20: USA | W20: Wire Transfer | X20: Delivered | Y20: NO | Z20: INV/2025/0015 | AA20: Online | AB20: 1st quarter | AC20: 5 | AD20: 2025 | AE20: Net 60 | AG20: 0.08 | AJ20: 1,02 | AK20: FedEx | AL20: FX709356414 | AM20: 24.8 kg | AN20: Warehouse C | AO20: 356 | AR20: No | AS20: wrong item | AT20: 15 % | AU20: 115,38 | AV20: Sophia Miller | AW20: Sophia Miller | AX20: VIP customer
A21: TR-2025016 | B21: 2025-01-16 | C21: 30.01.2025 | D21: P-014 | E21: license max 14 | F21: Software | G21: 1 | H21: 1166.96 | I21: 0.1 | J21: 1166.96 | K21: USD | L21: E005 | N21: North | O21: Houston | P21: VORTEX INC. | Q21: EIN: 517630478 | R21: john.yahoo.com | S21: (369) 698-1979 | T21: 990 Johnson Ave | U21: 85526 | V21: usa | W21: Wire Transfer | X21: Cancelled | Y21: Partial | Z21: INV/2025/0016 | AA21: Store | AB21: Q3 | AC21: January | AD21: 2025 | AE21: Net 60 | AF21: 7 | AG21: 0.08 | AJ21: 43.48 | AK21: Fed Ex | AL21: DH994024254 | AM21: 12.9 kg | AN21: wh b | AO21: 350 | AP21: 4 | AQ21: complaint | AR21: yes | AS21: damaged | AT21: 25% | AU21: #N/A | AV21: john johnson | AW21: John Johnson | AX21: check price
A22: TR-2025017 | B22: 08/09/2026 | C22: 18.08.2026 | D22: P-054 | E22: Mouse Basic 54 | F22: Office | G22: 18 kom | H22: 801,23 | I22: 5% | J22: USD 14,422 | K22: USD | L22: EMP5 | M22: null | N22: East | O22: Los Angles | P22: Wayne LLC | Q22: EIN: 852761906 | R22: sophia.yahoo.com | S22: +1 352 452 1730 | T22: 648 Wilson Street | U22: 21467 | V22: USA | W22: Cash | X22: Processing | Y22: YES | Z22: INV/2026/0017 | AA22: online | AB22: Q1 | AC22: 8 | AD22: 2026 | AE22: 15 | AF22: 72 | AG22: 0,08 | AJ22: 13.08 USD | AK22: FedEx | AL22: FX923827298 | AM22: 17.83 | AN22: Warehouse B | AO22: 102 | AP22: excellent | AR22: No | AT22: 25% | AU22: 432,66 | AV22: Sophia Taylor | AW22: Sophia Taylor | AX22: duplicate?
A23: TR-2025018 | B23: 20250503 | C23: 20250505 | D23: p041 | E23: Monitor X 41 | F23: SOFTWARE | G23: 6 | H23: 247.64 USD | I23: 0.1 | J23: 1485.84 USD | K23: USD | L23: E013 | M23: ROBERT WILLIAMS | N23: East | O23: seattle | P23: Stark INC | Q23: EIN: 375962955 | R23: david.gmail.com | S23: (588) 372-8231 | T23: 161 Brown Street | U23: 82088 | V23: US | W23: Wire Transfer | X23: Delivered | Y23: Partial | Z23: INV/2025/0018 | AA23: Online | AB23: Q4 | AC23: 5 | AD23: 2025 | AE23: Net 60 | AF23: 41 | AG23: 8 | AJ23: $5.78 | AK23: Fed Ex | AL23: DH160909509 | AM23: 13.6 kg | AN23: WH-A | AO23: 136 | AP23: 4 | AQ23: all good | AR23: No | AS23: damaged | AT23: 15 % | AU23: N/A | AV23: david miller | AW23: David Miller | AX23: urgent
A24: TR-2025019 | B24: 2025-08-05 | C24: 11-Aug-25 | D24: p033 | E24: - | F24: OFFICE | G24: 31 | H24: null | I24: 0.1 | J24: 4.000,86 | K24: USD | L24: E002 | M24: sarah wilson | N24: South | O24: BOSTON | P24: acme inc | Q24: EIN: 884743535 | R24: sophia.yahoo.com | S24: +1 796 515 4314 | T24: 862 Smith Ave | U24: 44937 | V24: usa | W24: Credit Card | X24: Delivered | Y24: Partial | Z24: INV/2025/0019 | AA24: Phone | AB24: q1 | AC24: Aug | AD24: 2025 | AE24: 15 | AF24: 23 | AG24: 0.08 | AJ24: 1.83 | AK24: DHL | AL24: 1Z482420536 | AM24: 15.64 | AN24: Warehouse B | AO24: 365 | AP24: 5/5 | AQ24: complaint | AR24: 0 | AS24: wrong item | AT24: 15 % | AU24: 120.03 USD | AV24: sophia jones | AW24: Sophia Jones | AX24: duplicate?
A26: TR-2025020 | B26: 2025-05-18 | C26: 05/20/2025 | D26: P-052 | E26: LAPTOP MAX 52 | F26: Furniture | G26: 16 kom. | H26: 1467.86 | I26: 10% | J26: - | K26: USD | L26: E018 | M26: #N/A | N26: South | O26: NY | P26: Stark INC | Q26: EIN: 901632584 | R26: emily.gmail.com | S26: +1 910 630 9611 | T26: 347 Davis St. | U26: 44919 | V26: U.S. | W26: Cash | X26: Cancelled | Y26: YES | Z26: INV/2025/0020 | AA26: Online | AB26: 1st quarter | AC26: May | AD26: 2025 | AE26: Net 60 | AF26: 31 | AG26: 8% | AJ26: 18,22 | AK26: UPS | AL26: FX315591108 | AM26: 0.7 kg | AN26: wh b | AP26: 1 | AQ26: complaint | AR26: 0 | AS26: doesn't fit | AT26: 0.3 | AU26: 704.57 | AV26: Emily Brown
A27: TR-2025021 | B27: 20260321 | C27: 24.03.2026 | D27: P_034 | F27: Office | G27: 3 kom | H27: 23,03 | I27: 0 | J27: #N/A | K27: EUR | L27: e-001 | M27: Sarah Wilson | N27: East | O27: Los Angles | P27: Initech inc | Q27: EIN: 650238460 | R27: david.company.com | S27: (561) 366-4908 | T27: 303 Smith Street | U27: 21783 | V27: U.S. | W27: Cash | X27: Cancelled | Y27: NO | Z27: INV/2026/0021 | AA27: Online | AB27: Q3 | AC27: March | AD27: 2026 | AE27: Net 60 | AF27: 13 | AG27: 0,08 | AJ27: 20.84 | AK27: USPS | AL27: 1Z761743464 | AM27: 18.36 | AN27: wh b | AO27: 137 | AP27: 3 | AQ27: OK | AR27: 1 | AT27: 25% | AU27: USD 2 | AV27: David Johnson | AW27: same | AX27: VIP customer
A28: TR-2025022 | B28: 04/24/2025 | C28: 30-Apr-25 | D28: P_055 | E28: Cable Basic 55 | F28: Office | G28: 29 kom. | H28: 921,78 | I28: 0.1 | J28: 26731.62 | K28: $ | L28: EMP9 | M28: #N/A | N28: North | O28: Houston | P28: INITECH INC | Q28: EIN: 930519543 | R28: emma.company.com | S28: (647) 729-9474 | T28: 609 Miller Blvd | U28: 02360 | V28: U.S. | W28: credit card | X28: Delivered | Y28: Partial | Z28: INV/2025/0022 | AA28: Store | AB28: Q3 | AC28: April | AD28: '25 | AE28: 15 | AF28: 24 | AG28: 8 | AJ28: 20.08 USD | AK28: DHL | AL28: FX842576360 | AM28: 24.5 kg | AN28: Warehouse B | AO28: 500 | AP28: 5 | AQ28: satisfied | AR28: NO | AT28: 0.3 | AU28: 801.95 | AV28: Emma Wilson | AW28: same | AX28: duplicate?
A29: TR-2025023 | B29: 01.08.2025. | C29: 08/03/2025 | D29: P-019 | E29: Monitor Max 19 | G29: 13 | H29: 251,62 | I29: 5% | J29: 3271,06 | K29: EUR | L29: e-017 | M29: Robert Davis | N29: NORTH | O29: Boston | P29: ACME LTD. | Q29: EIN: 758208298 | R29: james.gmail.com | S29: (900) 989-6289 | T29: 274 Johnson Street | U29: 46730 | V29: U.S. | W29: Wire Transfer | X29: Delivered | Y29: Paid | Z29: INV/2025/0023 | AA29: Web | AB29: Q2 | AC29: Aug | AD29: 2025 | AE29: immediate | AF29: 6 | AG29: 0,08 | AJ29: 11,14 | AK29: Fed Ex | AL29: FX106617834 | AM29: 9,18 | AN29: Warehouse B | AO29: 491 | AP29: 2 | AQ29: all good | AR29: 0 | AS29: wrong item | AT29: 15 % | AU29: 98,13 | AV29: James Williams | AW29: James Williams | AX29: urgent
A30: TR-2025024 | B30: 01/24/2026 | C30: 01/26/2026 | D30: P-011 | E30: Mouse Pro 11 | F30: Equipment | G30: 1 kom | H30: 858,95 | I30: 0.1 | J30: N/A | K30: usd | L30: e-012 | M30: #N/A | N30: west | O30: LA | P30: umbrella ltd. | Q30: 504686425 | R30: ryan.yahoo.com | S30: 923.467.8214 | T30: 377 Taylor St. | U30: 53972 | V30: US | W30: credit card | X30: Delivered | Y30: NO | Z30: INV/2026/0024 | AA30: online | AB30: Q1 | AC30: Jan | AD30: 2026 | AE30: immediate | AF30: 3 | AG30: 0,08 | AJ30: USD 16 | AK30: USPS | AL30: 1Z933371692 | AM30: 25.54 | AN30: Warehouse A | AO30: 287 | AP30: 4.5 | AQ30: complaint | AR30: Yes | AT30: 25% | AU30: 25.77 | AV30: ryan jones | AX30: VIP customer
A31: TR-2025025 | B31: 16-May-25 | C31: 20250517 | D31: P-055 | E31: cable basic 55 | F31: office | G31: 12 | H31: N/A | I31: 10 | J31: 11.061,36 | K31: usd | L31: E015 | M31: Sarah Jones | N31: NORTH | O31: chicago | P31: Wayne inc | Q31: EIN: 819550596 | R31: john.gmail.com | S31: (982) 995-5691 | T31: 811 Miller St. | U31: 46306 | V31: USA | W31: Wire Transfer | X31: Pending | Y31: NO | Z31: INV/2025/0025 | AA31: Phone | AB31: Q4 | AC31: May | AD31: 2025 | AE31: Net 60 | AF31: #N/A | AG31: 8 | AJ31: 46.51 | AK31: USPS | AL31: DH772107295 | AM31: 1.7 kg | AN31: Warehouse C | AO31: 433 | AP31: 3 | AQ31: OK | AR31: 1 | AT31: 25% | AU31: 331.84 | AV31: John Miller | AW31: same | AX31: duplicate?
A32: TR-2025026 | B32: 20250302 | C32: 2025-03-07 | D32: P-017 | E32: #N/A | F32: N/A | G32: 23 | H32: $1,313.33 | I32: 10% | J32: 30206,59 | K32: usd | L32: e-008 | M32: Michael Williams | N32: North | O32: los angeles | P32: ACME INC | Q32: 426314041 | R32: jessica.company.com | S32: (315) 365-6316 | T32: 12 Wilson Blvd | U32: 12006 | V32: United States | W32: PayPal | X32: DELIVERED | Y32: Unpaid | Z32: INV/2025/0026 | AA32: Online | AB32: Q4 | AC32: March | AD32: 2025 | AE32: immediate | AF32: 24 | AG32: 0.08 | AJ32: 0.42 | AK32: USPS | AL32: DH884520761 | AM32: 19.61 | AN32: Warehouse A | AO32: 12 | AP32: 3 | AQ32: late delivery!! | AR32: Yes | AT32: 15 % | AU32: 906.20 USD | AV32: Jessica Davis | AX32: VIP customer
A33: TR-2025027 | B33: 12/31/2025 | C33: null | D33: P-012 | E33: N/A | F33: Electronics | G33: 15 | H33: 823,88 | I33: 0.1 | J33: 12.358,20 | K33: USD | L33: E021 | M33: - | N33: North | O33: Chicago | P33: Stark inc | Q33: EIN: 253719173 | R33: jessica.gmail.com | S33: 209.882.3888 | T33: 169 Davis Ave | U33: 01549 | V33: U.S. | W33: PayPal | X33: Processing | Y33: YES | Z33: INV/2025/0027 | AA33: Web | AB33: Q2 | AC33: 12 | AD33: '25 | AE33: Net 60 | AF33: 66 | AG33: 0,08 | AJ33: 48,72 | AK33: FedEx | AL33: DH826328507 | AM33: 19.8 kg | AN33: Warehouse B | AO33: 246 | AP33: 3 | AQ33: late delivery!! | AR33: 1 | AS33: damaged | AT33: 15 % | AU33: N/A | AV33: jessica williams | AW33: same | AX33: duplicate?
A34: TR-2025028 | B34: 18-Aug-26 | C34: 23.08.2026 | D34: p024 | E34: - | F34: Electronics | G34: 24 | H34: 95.70 USD | I34: 10% | J34: 2296.80 USD | K34: EUR | L34: E018 | M34: John Miller | N34: West | O34: Huston | P34: Stark LLC | Q34: 932128440 | R34: robert.yahoo.com | S34: +1 248 581 1683 | T34: 308 Johnson St. | U34: 56833 | V34: USA | W34: wire | X34: delivered | Y34: YES | Z34: INV/2026/0028 | AA34: Online | AB34: Q4 | AC34: August | AD34: 2026 | AE34: Net 60 | AF34: 43 | AG34: 8% | AJ34: 41.28 | AK34: DHL | AL34: DH663401775 | AM34: 1,4 | AN34: Warehouse B | AO34: 51 | AP34: 5/5 | AQ34: complaint | AT34: 25% | AU34: - | AV34: robert brown | AW34: Robert
A35: TR-2025029 | B35: 15.05.2026. | C35: 20260520 | D35: p051 | E35: Cable Basic 51 | F35: office | G35: 5 kom. | I35: 10% | J35: 5.183,25 | K35: EUR | L35: E001 | M35: Sarah Wilson | N35: South | O35: NY | P35: Globex INC | Q35: 434209630 | R35: chris.gmail.com | S35: (569) 944-8663 | T35: 344 Anderson Blvd | U35: 44749 | V35: US | W35: Wire Transfer | X35: DELIVERED | Y35: Paid | Z35: INV/2026/0029 | AA35: Web | AB35: Q4 | AC35: May | AD35: 2026 | AE35: Net 60 | AF35: 49 | AG35: 0.08 | AJ35: 17,84 | AK35: Fed Ex | AL35: DH136627024 | AM35: 27.46 | AN35: wh b | AO35: 324 | AP35: 2 | AQ35: late delivery!! | AR35: 1 | AS35: damaged | AT35: 0,18 | AU35: 155.50 USD | AV35: CHRIS JONES | AW35: same | AX35: check price
A36: TR-2025030 | B36: 20-Feb-26 | C36: 03/01/2026 | D36: p056 | E36: Keyboard X 56 | F36: Software | G36: 4 | H36: 1.111,11 | I36: 0.1 | J36: $4,444.44 | K36: EUR | L36: EMP18 | M36: - | N36: west | O36: CHICAGO | P36: Wayne inc | Q36: EIN: 620244895 | R36: emma.gmail.com | S36: (463) 759-1378 | T36: 49 Davis Blvd | U36: 27259 | V36: United States | W36: wire | X36: Pending | Y36: Paid | Z36: INV/2026/0030 | AA36: Web | AB36: q1 | AC36: Feb | AD36: 2026 | AE36: 15 | AG36: 0.08 | AJ36: 35.95 | AK36: DHL | AL36: DH116113610 | AM36: 27.7 kg | AN36: Warehouse A | AO36: 332 | AP36: 5/5 | AQ36: all good | AR36: No | AS36: wrong item | AT36: 25% | AU36: 133.33 | AV36: Emma Miller | AX36: VIP customer
A37: TR-2025031 | B37: 27.01.2025. | C37: 20250208 | D37: p056 | E37: KEYBOARD X 56 | F37: Software | G37: 37 | H37: 1111.11 | J37: null | K37: $ | L37: E001 | M37: Sarah Wilson | N37: West | O37: Chicgo | P37: Acme LLC | Q37: EIN: 241588570 | R37: daniel.gmail.com | S37: (302) 871-6939 | T37: 640 Williams Street | U37: 08886 | V37: US | W37: wire | X37: delivered | Y37: Unpaid | Z37: INV/2025/0031 | AA37: online | AB37: 1st quarter | AC37: Jan | AD37: 2025 | AE37: 15 | AF37: 20 | AG37: 0.08 | AJ37: 38,91 | AK37: ups | AL37: 1Z783034651 | AM37: 27.38 | AN37: Warehouse B | AO37: 404 | AP37: 2 | AR37: 0 | AT37: 25% | AU37: 1233.33 USD | AV37: Daniel Miller | AW37: Daniel | AX37: VIP customer
A38: TR-2025032 | B38: 2025-08-18 | C38: 08/22/2025 | D38: P-059 | E38: Keyboard Max 59 | F38: - | G38: 17 kom | H38: 673.61 | I38: 10 | J38: 11451.37 USD | K38: usd | L38: EMP13 | M38: Robert Williams | N38: South | O38: NYC | P38: WAYNE LLC | Q38: EIN: 250107754 | S38: (355) 209-3185 | T38: 476 Davis Street | U38: 55290 | V38: usa | W38: Cash | X38: Delivered | Y38: YES | Z38: INV/2025/0032 | AA38: Web | AB38: q1 | AC38: Aug | AD38: '25 | AE38: Net 30 | AF38: null | AG38: 0,08 | AJ38: 28.74 | AK38: FedEx | AL38: 1Z439828953 | AM38: 2.03 | AN38: Warehouse C | AO38: N/A | AP38: 4.5 | AQ38: all good | AR38: 0 | AS38: doesn't fit | AT38: 15 % | AU38: 343.54 | AV38: John Jones | AW38: same
A39: TR-2025193 | B39: 01/22/2025 | C39: 02/03/2025 | D39: P21 | E39: Monitor Max 21 | F39: N/A | G39: 30 | H39: 1184,70 | I39: 10 | J39: 35541,00 | K39: usd | L39: E012 | M39: #N/A | N39: NORTH | O39: NY | P39: Acme Inc. | Q39: 499269182 | R39: laura.gmail.com | S39: (798) 468-6016 | T39: 428 Jones Street | U39: 51354 | V39: United States | W39: wire | X39: delivered | Y39: NO | Z39: INV/2025/0193 | AA39: Store | AB39: Q3 | AC39: Jan | AD39: 2025 | AE39: immediate | AF39: 84 | AG39: 0.08 | AJ39: 21.04 | AK39: ups | AL39: FX387168701 | AM39: 25.4 kg | AN39: Warehouse B | AO39: 197 | AP39: 2 | AQ39: all good | AR39: 0 | AU39: 1066.23 | AV39: Laura Williams | AW39: same | AX39: duplicate?
A40: TR-2025033 | B40: 01.07.2025. | C40: 02-Jul-25 | D40: P18 | E40: license basic 18 | F40: Equipment | G40: 17 kom | H40: USD 1,470 | J40: USD 24,996 | K40: usd | L40: E023 | M40: Laura Anderson | N40: West | O40: New York | P40: acme inc | Q40: EIN: 755957168 | R40: david.gmail.com | S40: 615.910.6314 | T40: 662 Wilson Ave | U40: 60702 | V40: USA | W40: Wire Transfer | X40: Pending | Y40: NO | Z40: INV/2025/0033 | AA40: Phone | AB40: Q3 | AC40: July | AD40: '25 | AE40: immediate | AF40: 30 | AG40: 8 | AJ40: 17.76 | AK40: DHL | AL40: FX758003774 | AM40: 2,25 | AN40: WH-A | AO40: 473 | AP40: 5 | AQ40: late delivery!! | AR40: 1 | AS40: wrong item | AT40: 0.3 | AU40: 749,88 | AV40: David Johnson | AX40: duplicate?
A41: TR-2025034 | B41: 2025-06-23 | C41: 20250704 | D41: P-014 | E41: License Max 14 | F41: Software | G41: 24 kom | H41: USD 1,167 | I41: 0.1 | J41: #N/A | K41: USD | L41: E017 | M41: N/A | N41: East | O41: miami | P41: Globex LLC | Q41: EIN: 509238663 | R41: sarah.gmail.com | S41: +1 259 804 3923 | T41: 939 Miller Ave | U41: 32697 | V41: usa | W41: Credit Card | X41: DELIVERED | Y41: NO | Z41: INV/2025/0034 | AA41: Phone | AB41: Q1 | AC41: 6 | AD41: 2025 | AE41: immediate | AF41: 37 | AG41: 0.08 | AJ41: 46.03 | AK41: UPS | AL41: 1Z865080132 | AM41: 12,99 | AN41: Warehouse B | AO41: 180 | AP41: 3 | AQ41: satisfied | AR41: NO | AS41: doesn't fit | AT41: 0.3 | AU41: 840.21 | AV41: Sarah Williams | AW41: Sarah | AX41: VIP customer
A42: TR-2025035 | B42: 27-Jan-25 | C42: 2025-02-04 | D42: P-060 | E42: Desk Basic 60 | F42: Electronics | G42: 38 kom. | H42: 334.59 USD | I42: 10% | J42: 12.714,42 | K42: EUR | L42: E021 | M42: N/A | N42: West | O42: NYC | P42: Umbrella LLC | Q42: EIN: 250559903 | R42: olivia.gmail.com | S42: 390.751.5500 | T42: 269 Johnson Ave | U42: 51295 | V42: United States | W42: wire | X42: Cancelled | Y42: YES | Z42: INV/2025/0035 | AA42: Phone | AB42: Q4 | AC42: 1 | AD42: 2025 | AE42: Net 60 | AF42: 31 | AG42: 8 | AJ42: $42.83 | AK42: Fed Ex | AL42: 1Z322808127 | AM42: 11.3 kg | AN42: Warehouse C | AO42: 72 | AP42: 5/5 | AQ42: all good | AR42: yes | AS42: doesn't fit | AT42: 25% | AU42: 381.43 | AV42: Olivia Wilson
A43: TR-2025036 | B43: 26.03.2026. | C43: 03-Apr-26 | D43: P-018 | E43: license basic 18 | F43: EQUIPMENT | G43: 13 | H43: 1470.36 | I43: 5% | J43: 19.114,68 | K43: $ | L43: e-008 | M43: Michael Williams | N43: South | O43: Chicago | P43: Vortex Ltd. | Q43: EIN: 858287081 | R43: emma.company.com | S43: 500.976.4812 | T43: 817 Miller St. | U43: 41575 | V43: United States | W43: wire | X43: delivered | Y43: paid | Z43: INV/2026/0036 | AA43: Web | AB43: Q2 | AC43: 3 | AD43: 2026 | AE43: immediate | AF43: 19 | AG43: 0,08 | AJ43: 32.74 | AK43: ups | AL43: 1Z881941210 | AM43: 5.6 | AN43: Warehouse B | AO43: 62 | AP43: 4 | AS43: doesn't fit | AT43: 25% | AU43: $573.44 | AV43: EMMA BROWN | AW43: Emma Brown | AX43: urgent
...

Sheet PivotChartRepCommission
A1: Row Labels | B1: Sum of Rep Commission
A2: E001 | B2: 7254.1719
A3: E002 | B3: 5397.9858
A4: E003 | B4: 6186.3912
A5: E004 | B5: 8268.362
A6: E005 | B6: 6276.0839
A7: E006 | B7: 8969.9147
A8: E007 | B8: 3689.322
A9: E008 | B9: 7027.1083
A10: E009 | B10: 8450.572
A11: E010 | B11: 4987.8695
A12: E011 | B12: 1180.6019
A13: E012 | B13: 4796.6891
... A27: Grand Total | B27: 136678.65

Sheet PivotChartDepartmentProfit
A1: Row Labels | B1: Sum of Profit
A2: Online | B2: 167469.84
A3: Retail | B3: 129231.36
A4: Sales | B4: 192890.22
A5: Wholesale | B5: 224800.04
A6: Grand Total | B6: 714391.45

Sheet PivotChartTrend
A1: Row Labels | B1: Sum of Profit
A2: January | B2: 66014.064
A3: February | B3: 73288.987
A4: March | B4: 74549.902
A5: April | B5: 55299.642
A6: May | B6: 74952.254
A7: June | B7: 94160.644
A8: July | B8: 88210.536
A9: August | B9: 70481.925
A10: September | B10: 31947.528
A11: October | B11: 24843.26
A12: November | B12: 29531.663
A13: December | B13: 31111.042
A14: Grand Total | B14: 714391.45

Sheet Sales_RAW(AFTER)
A4: Transaction ID | B4: Date | C4: Delivery Date | D4: Product Code | E4: Product Name | F4: Supplier | G4: Category | H4: Quantity | I4: Unit Price | J4: Discount % | K4: Total | L4: Currency | M4: Employee ID | N4: Sales Rep | O4: Department | P4: Region | Q4: City | R4: Customer | S4: Tax ID | T4: CUSTOMER EMAIL | U4: Phone | V4: Address | W4: ZIP Code | X4: Country | Y4: Payment Method | Z4: Status | AA4: Payment Status | AB4: Invoice No. | AC4: Sales Channel | AD4: Quarter | AE4: Month | AF4: Year | AG4: Payment Terms | AH4: Days Overdue | AI4: VAT | AJ4: VAT Amount | AK4: Amount incl. VAT | AL4: Shipping Cost | AM4: Courier | AN4: Tracking no. | AO4: Weight (KG) | AP4: Warehouse | AQ4: Stock | AR4: Customer Rating | AS4: Comment | AT4: Returned? | AU4: Return reason | AV4: Margin | AW4: Rep Commission | AX4: Customer Full Name | AY4: Contact Person | AZ4: Notes | BA4: Price With Discount | BB4: Warranty | BC4: Profit
A5: TR-2025001 | B5: 45909 | C5: 45923 | D5: ="P-" & TEXT(VALUE(SUBSTITUTE(SUBSTITUTE(SUBSTITUTE(UPPER(TRIM('Sales_RAW(BEFORE)'!D5)), "P", ""), "-", ""), "_", "")),"000") -> P-033 | E5: =PROPER(TRIM('Sales_RAW(BEFORE)'!E5)) -> Printer X 33 | F5: =_xlfn.XLOOKUP(E5,Product_List!$B$2:$B$61,Product_List!$E$2:$E$61,2) -> Global Distrib | G5: =VLOOKUP(E5,Product_List!$B$2:$C$61,2,FALSE) -> Office | H5: =SUBSTITUTE(SUBSTITUTE('Sales_RAW(BEFORE)'!G5,"kom",""),".","") -> 7 | I5: =VLOOKUP(E5,Product_List!$B$2:$D$61,3,FALSE) -> 129.06 | J5: =IF(IFERROR(VALUE(SUBSTITUTE(SUBSTITUTE(TRIM('Sales_RAW(BEFORE)'!I5), "%", ""), ",", ".")), 0) > 1, IFERROR(VALUE(SUBSTITUTE(SUBSTITUTE(TRIM('Sales_RAW(BEFORE)'!I5), "%", ""), ",", ".")), 0) / 100, IFERROR(VALUE(SUBSTITUTE(SUBSTITUTE(TRIM('Sales_RAW(BEFORE)'!I5), "%", ""), ",", ".")), 0)) -> 0.1 | K5: =IFERROR(H5*I5,0) -> 903.42 | L5: {=_xlfn.LET( _xlpm.valuta, UPPER(TRIM('Sales_RAW(BEFORE)'!K5)), _xlfn.IFS( _xlpm.valuta = "", "", OR(_xlpm.valuta = "USD", _xlpm.valuta = "$"), "$", OR(_xlpm.valuta = "EUR", _xlpm.valuta = "€"), "€", TRUE, _xlpm.valuta ) )} -> $ | M5: ="E" & TEXT(VALUE(SUBSTITUTE(SUBSTITUTE(SUBSTITUTE(UPPER(TRIM('Sales_RAW(BEFORE)'!L5)), "EMP", ""), "E", ""), "-", "")),"000") -> E016 | N5: =_xlfn.XLOOKUP(M5,Employees!$D$2:$D$26,Employees!$A$2:$A$26) -> Chris Anderson | O5: =_xlfn.XLOOKUP(N5,Employees!$A$2:$A$26,Employees!$C$2:$C$26,2) -> Online | P5: =PROPER('Sales_RAW(BEFORE)'!N5) -> East | Q5: =VLOOKUP(N5,Employees!$A$2:$B$26,2,FALSE) -> Chicago | R5: =PROPER('Sales_RAW(BEFORE)'!P5) -> Wayne Llc | S5: =SUBSTITUTE(SUBSTITUTE('Sales_RAW(BEFORE)'!Q5,"EIN",""),":","") -> 388875967 | T5: daniel.gmail.com | U5: (536) 760-6300 | V5: 344 Davis Street | W5: 63212 | X5: USA | Y5: =PROPER('Sales_RAW(BEFORE)'!W5) -> Credit Card | Z5: =PROPER('Sales_RAW(BEFORE)'!X5) -> Delivered | AA5: {=_xlfn.LET( _xlpm.val, TRIM(LOWER('Sales_RAW(BEFORE)'!Y5)), _xlfn.IFS( OR(_xlpm.val="yes", _xlpm.val="paid"), "Paid", OR(_xlpm.val="no", _xlpm.val="unpaid"), "Unpaid", OR(_xlpm.val="partial", _xlpm.val="partial paid"), "Partial", _xlpm.val="", "", TRUE, 'Sales_RAW(BEFORE)'!AY5 ) )} -> Paid | AB5: INV/2025/0001 | AC5: =PROPER('Sales_RAW(BEFORE)'!AA5) -> Online | AD5: =SUBSTITUTE(SUBSTITUTE(SUBSTITUTE(SUBSTITUTE('Sales_RAW(BEFORE)'!AB5,"st",""),"q",""),"Q",""),"uarter","") -> 1 | AE5: =TEXT(IFERROR(DATEVALUE('Sales_RAW(BEFORE)'!AC5 & " 1"), IFERROR(DATE(2025, 'Sales_RAW(BEFORE)'!AC5, 1), 'Sales_RAW(BEFORE)'!AC5)), "mmmm") -> September | AF5: =_xlfn.LET( _xlpm.raw, TRIM(SUBSTITUTE('Sales_RAW(BEFORE)'!AD5, "'", "")), _xlpm.num, IFERROR(VALUE(_xlpm.raw), 0), IF(_xlpm.num < 100, 2000 + _xlpm.num, _xlpm.num) ) -> 2025 | AG5: =PROPER('Sales_RAW(BEFORE)'!AE5) -> Immediate | AH5: {=_xlfn.LET( _xlpm.val, LOWER(TRIM('Sales_RAW(BEFORE)'!AF5)), _xlfn.IFS( OR(_xlpm.val="", _xlpm.val="null", _xlpm.val="N/A", _xlpm.val="-", _xlpm.val="#N/A"), 0, ISNUMBER('Sales_RAW(BEFORE)'!AF5), 'Sales_RAW(BEFORE)'!AF5, TRUE, IFERROR(_xlfn.NUMBERVALUE(_xlpm.val), 0) ) )} -> 0 | AI5: =IF(IFERROR(VALUE(SUBSTITUTE(SUBSTITUTE(TRIM('Sales_RAW(BEFORE)'!AG5), "%", ""), ",", ".")), 0) > 1, IFERROR(VALUE(SUBSTITUTE(SUBSTITUTE(TRIM('Sales_RAW(BEFORE)'!AG5), "%", ""), ",", ".")), 0) / 100, IFERROR(VALUE(SUBSTITUTE(SUBSTITUTE(TRIM('Sales_RAW(BEFORE)'!AG5), "%", ""), ",", ".")), 0)) -> 0.08 | AJ5: =K5*AI5 -> 72.2736 | AK5: =AJ5+K5 -> 975.6936 | AL5: =IFERROR(VALUE(SUBSTITUTE(SUBSTITUTE(SUBSTITUTE('Sales_RAW(BEFORE)'!AJ5,"$",""),"USD",""),",",".")),0) -> 15.21 | AM5: =SUBSTITUTE(SUBSTITUTE(PROPER('Sales_RAW(BEFORE)'!AK5), "Fed Ex", "FedEx"),"Fedex","FedEx") -> Dhl | AN5: 1Z806032141 | AO5: =SUBSTITUTE('Sales_RAW(BEFORE)'!AM5,"kg","") -> 23.5 | AP5: =_xlfn.LET( _xlpm.raw, UPPER(TRIM('Sales_RAW(BEFORE)'!AN5)), _xlpm.clean, RIGHT(_xlpm.raw, 1), IF(OR(_xlpm.raw="", _xlpm.raw="null"), "N/A", _xlpm.clean) ) -> B | AQ5: 76 | AR5: {=_xlfn.LET( _xlpm.raw, LOWER(TRIM('Sales_RAW(BEFORE)'!AP5)), _xlfn.IFS( OR(_xlpm.raw="", _xlpm.raw="null"), "", _xlpm.raw="excellent", 5, _xlpm.raw="good", 4, _xlpm.raw="average", 3, _xlpm.raw="poor", 2, _xlpm.raw="terrible", 1, ISNUMBER(SEARCH("/", _xlpm.raw)), _xlfn.NUMBERVALUE(_xlfn.TEXTBEFORE(_xlpm.raw, "/")), TRUE, IFERROR(_xlfn.NUMBERVALUE(_xlpm.raw), "") ) )} -> 3 | AS5: OK | AT5: No | AV5: =IF(IFERROR(VALUE(SUBSTITUTE(SUBSTITUTE(TRIM('Sales_RAW(BEFORE)'!AT5), "%", ""), ",", ".")), 0) > 1, IFERROR(VALUE(SUBSTITUTE(SUBSTITUTE(TRIM('Sales_RAW(BEFORE)'!AT5), "%", ""), ",", ".")), 0) / 100, IFERROR(VALUE(SUBSTITUTE(SUBSTITUTE(TRIM('Sales_RAW(BEFORE)'!AT5), "%", ""), ",", ".")), 0)) -> 0 | AW5: =BA5*(_xlfn.XLOOKUP(N5,Employees!$A$2:$A$26,Employees!$E$2:$E$26,2)) -> 23.416646 | AX5: =PROPER('Sales_RAW(BEFORE)'!AV5) -> Daniel Davis | AY5: =AX5 -> Daniel Davis | AZ5: Duplicate | BA5: =AK5*(1-(_xlfn.XLOOKUP(G5, Exchange_Rates!$B$8:$F$8, Exchange_Rates!$B$9:$F$9, 0)+J5)) -> 780.55488 | BB5: {=_xlfn.LET( _xlpm.raw_dt, SUBSTITUTE(TRIM(C5), ".", "/"), _xlpm.dt, IFERROR(DATEVALUE(_xlpm.raw_dt), C5), _xlpm.p_code, TRIM(E5), _xlpm.w_text, LOWER(_xlfn.XLOOKUP(_xlpm.p_code, Product_List!$B$2:$B$61, Product_List!$F$2:$F$61, "24")), _xlpm.m_count, _xlfn.IFS( ISNUMBER(SEARCH("36", _xlpm.w_text)), 36, ISNUMBER(SEARCH("3 yr", _xlpm.w_text)), 36, ISNUMBER(SEARCH("12", _xlpm.w_text)), 12, ISNUMBER(SEARCH("1 yr", _xlpm.w_text)), 12, TRUE, 24 ), IFERROR(EDATE(_xlpm.dt, _xlpm.m_count), "Proveri datum") )} -> 46653 | BC5: =BA5*AV5 -> 0
A6: TR-2025002 | B6: 45893 | C6: 45900 | D6: ="P-" & TEXT(VALUE(SUBSTITUTE(SUBSTITUTE(SUBSTITUTE(UPPER(TRIM('Sales_RAW(BEFORE)'!D6)), "P", ""), "-", ""), "_", "")),"000") -> P-052 | E6: =VLOOKUP(D6,Product_List!$A$2:$B$61,2,FALSE) -> Laptop Max 52 | F6: =_xlfn.XLOOKUP(E6,Product_List!$B$2:$B$61,Product_List!$E$2:$E$61,2) -> TechSupply Co | G6: =VLOOKUP(E6,Product_List!$B$2:$C$61,2,FALSE) -> Furniture | H6: =SUBSTITUTE(SUBSTITUTE('Sales_RAW(BEFORE)'!G6,"kom",""),".","") -> 2 | I6: =VLOOKUP(E6,Product_List!$B$2:$D$61,3,FALSE) -> 1467.86 | J6: =IF(IFERROR(VALUE(SUBSTITUTE(SUBSTITUTE(TRIM('Sales_RAW(BEFORE)'!I6), "%", ""), ",", ".")), 0) > 1, IFERROR(VALUE(SUBSTITUTE(SUBSTITUTE(TRIM('Sales_RAW(BEFORE)'!I6), "%", ""), ",", ".")), 0) / 100, IFERROR(VALUE(SUBSTITUTE(SUBSTITUTE(TRIM('Sales_RAW(BEFORE)'!I6), "%", ""), ",", ".")), 0)) -> 0.1 | K6: =IFERROR(H6*I6,0) -> 2935.72 | L6: {=_xlfn.LET( _xlpm.valuta, UPPER(TRIM('Sales_RAW(BEFORE)'!K6)), _xlfn.IFS( _xlpm.valuta = "", "", OR(_xlpm.valuta = "USD", _xlpm.valuta = "$"), "$", OR(_xlpm.valuta = "EUR", _xlpm.valuta = "€"), "€", TRUE, _xlpm.valuta ) )} -> $ | M6: ="E" & TEXT(VALUE(SUBSTITUTE(SUBSTITUTE(SUBSTITUTE(UPPER(TRIM('Sales_RAW(BEFORE)'!L6)), "EMP", ""), "E", ""), "-", "")),"000") -> E023 | N6: =_xlfn.XLOOKUP(M6,Employees!$D$2:$D$26,Employees!$A$2:$A$26) -> Laura Anderson | O6: =_xlfn.XLOOKUP(N6,Employees!$A$2:$A$26,Employees!$C$2:$C$26,2) -> Sales | P6: =PROPER('Sales_RAW(BEFORE)'!N6) -> North | Q6: =VLOOKUP(N6,Employees!$A$2:$B$26,2,FALSE) -> Seattle | R6: =PROPER('Sales_RAW(BEFORE)'!P6) -> Wayne Inc | S6: =SUBSTITUTE(SUBSTITUTE('Sales_RAW(BEFORE)'!Q6,"EIN",""),":","") -> 790161495 | T6: john.company.com | U6: +1 836 781 3186 | V6: 276 Johnson St. | W6: 89566 | X6: USA | Y6: =PROPER('Sales_RAW(BEFORE)'!W6) -> Cash | Z6: =PROPER('Sales_RAW(BEFORE)'!X6) -> Cancelled | AA6: {=_xlfn.LET( _xlpm.val, TRIM(LOWER('Sales_RAW(BEFORE)'!Y6)), _xlfn.IFS( OR(_xlpm.val="yes", _xlpm.val="paid"), "Paid", OR(_xlpm.val="no", _xlpm.val="unpaid"), "Unpaid", OR(_xlpm.val="partial", _xlpm.val="partial paid"), "Partial", _xlpm.val="", "", TRUE, 'Sales_RAW(BEFORE)'!AY6 ) )} -> Partial | AB6: INV/2025/0002 | AC6: =PROPER('Sales_RAW(BEFORE)'!AA6) -> Phone | AD6: =SUBSTITUTE(SUBSTITUTE(SUBSTITUTE(SUBSTITUTE('Sales_RAW(BEFORE)'!AB6,"st",""),"q",""),"Q",""),"uarter","") -> 1 | AE6: =TEXT(IFERROR(DATEVALUE('Sales_RAW(BEFORE)'!AC6 & " 1"), IFERROR(DATE(2025, 'Sales_RAW(BEFORE)'!AC6, 1), 'Sales_RAW(BEFORE)'!AC6)), "mmmm") -> August | AF6: =_xlfn.LET( _xlpm.raw, TRIM(SUBSTITUTE('Sales_RAW(BEFORE)'!AD6, "'", "")), _xlpm.num, IFERROR(VALUE(_xlpm.raw), 0), IF(_xlpm.num < 100, 2000 + _xlpm.num, _xlpm.num) ) -> 2025 | AG6: =PROPER('Sales_RAW(BEFORE)'!AE6) -> Net 60 | AH6: {=_xlfn.LET( _xlpm.val, LOWER(TRIM('Sales_RAW(BEFORE)'!AF6)), _xlfn.IFS( OR(_xlpm.val="", _xlpm.val="null", _xlpm.val="N/A", _xlpm.val="-", _xlpm.val="#N/A"), 0, ISNUMBER('Sales_RAW(BEFORE)'!AF6), 'Sales_RAW(BEFORE)'!AF6, TRUE, IFERROR(_xlfn.NUMBERVALUE(_xlpm.val), 0) ) )} -> 10 | AI6: =IF(IFERROR(VALUE(SUBSTITUTE(SUBSTITUTE(TRIM('Sales_RAW(BEFORE)'!AG6), "%", ""), ",", ".")), 0) > 1, IFERROR(VALUE(SUBSTITUTE(SUBSTITUTE(TRIM('Sales_RAW(BEFORE)'!AG6), "%", ""), ",", ".")), 0) / 100, IFERROR(VALUE(SUBSTITUTE(SUBSTITUTE(TRIM('Sales_RAW(BEFORE)'!AG6), "%", ""), ",", ".")), 0)) -> 0.08 | AJ6: =K6*AI6 -> 234.8576 | AK6: =AJ6+K6 -> 3170.5776 | AL6: =IFERROR(VALUE(SUBSTITUTE(SUBSTITUTE(SUBSTITUTE('Sales_RAW(BEFORE)'!AJ6,"$",""),"USD",""),",",".")),0) -> 14.48 | AM6: =SUBSTITUTE(SUBSTITUTE(PROPER('Sales_RAW(BEFORE)'!AK6), "Fed Ex", "FedEx"),"Fedex","FedEx") -> Ups | AN6: FX515375252 | AO6: =SUBSTITUTE('Sales_RAW(BEFORE)'!AM6,"kg","") -> 6,4 | AP6: =_xlfn.LET( _xlpm.raw, UPPER(TRIM('Sales_RAW(BEFORE)'!AN6)), _xlpm.clean, RIGHT(_xlpm.raw, 1), IF(OR(_xlpm.raw="", _xlpm.raw="null"), "N/A", _xlpm.clean) ) -> A | AQ6: 72 | AR6: {=_xlfn.LET( _xlpm.raw, LOWER(TRIM('Sales_RAW(BEFORE)'!AP6)), _xlfn.IFS( OR(_xlpm.raw="", _xlpm.raw="null"), "", _xlpm.raw="excellent", 5, _xlpm.raw="good", 4, _xlpm.raw="average", 3, _xlpm.raw="poor", 2, _xlpm.raw="terrible", 1, ISNUMBER(SEARCH("/", _xlpm.raw)), _xlfn.NUMBERVALUE(_xlfn.TEXTBEFORE(_xlpm.raw, "/")), TRUE, IFERROR(_xlfn.NUMBERVALUE(_xlpm.raw), "") ) )} -> 5 | AS6: all good | AV6: =IF(IFERROR(VALUE(SUBSTITUTE(SUBSTITUTE(TRIM('Sales_RAW(BEFORE)'!AT6), "%", ""), ",", ".")), 0) > 1, IFERROR(VALUE(SUBSTITUTE(SUBSTITUTE(TRIM('Sales_RAW(BEFORE)'!AT6), "%", ""), ",", ".")), 0) / 100, IFERROR(VALUE(SUBSTITUTE(SUBSTITUTE(TRIM('Sales_RAW(BEFORE)'!AT6), "%", ""), ",", ".")), 0)) -> 0.15 | AW6: =BA6*(_xlfn.XLOOKUP(N6,Employees!$A$2:$A$26,Employees!$E$2:$E$26,2)) -> 50.729242 | AX6: =PROPER('Sales_RAW(BEFORE)'!AV6) -> John Williams | AY6: =AX6 -> John Williams | AZ6: Urgent | BA6: =AK6*(1-(_xlfn.XLOOKUP(G6, Exchange_Rates!$B$8:$F$8, Exchange_Rates!$B$9:$F$9, 0)+J6)) -> 2536.4621 | BB6: {=_xlfn.LET( _xlpm.raw_dt, SUBSTITUTE(TRIM(C6), ".", "/"), _xlpm.dt, IFERROR(DATEVALUE(_xlpm.raw_dt), C6), _xlpm.p_code, TRIM(E6), _xlpm.w_text, LOWER(_xlfn.XLOOKUP(_xlpm.p_code, Product_List!$B$2:$B$61, Product_List!$F$2:$F$61, "24")), _xlpm.m_count, _xlfn.IFS( ISNUMBER(SEARCH("36", _xlpm.w_text)), 36, ISNUMBER(SEARCH("3 yr", _xlpm.w_text)), 36, ISNUMBER(SEARCH("12", _xlpm.w_text)), 12, ISNUMBER(SEARCH("1 yr", _xlpm.w_text)), 12, TRUE, 24 ), IFERROR(EDATE(_xlpm.dt, _xlpm.m_count), "Proveri datum") )} -> 46996 | BC6: =BA6*AV6 -> 380.46931
A7: TR-2025003 | B7: 46119 | C7: 46125 | D7: ="P-" & TEXT(VALUE(SUBSTITUTE(SUBSTITUTE(SUBSTITUTE(UPPER(TRIM('Sales_RAW(BEFORE)'!D7)), "P", ""), "-", ""), "_", "")),"000") -> P-032 | E7: =VLOOKUP(D7,Product_List!$A$2:$B$61,2,FALSE) -> Cable Basic 32 | F7: =_xlfn.XLOOKUP(E7,Product_List!$B$2:$B$61,Product_List!$E$2:$E$61,2) -> OfficeHub | G7: =VLOOKUP(E7,Product_List!$B$2:$C$61,2,FALSE) -> Software | H7: =SUBSTITUTE(SUBSTITUTE('Sales_RAW(BEFORE)'!G7,"kom",""),".","") -> 20 | I7: =VLOOKUP(E7,Product_List!$B$2:$D$61,3,FALSE) -> 1479.77 | J7: =IF(IFERROR(VALUE(SUBSTITUTE(SUBSTITUTE(TRIM('Sales_RAW(BEFORE)'!I7), "%", ""), ",", ".")), 0) > 1, IFERROR(VALUE(SUBSTITUTE(SUBSTITUTE(TRIM('Sales_RAW(BEFORE)'!I7), "%", ""), ",", ".")), 0) / 100, IFERROR(VALUE(SUBSTITUTE(SUBSTITUTE(TRIM('Sales_RAW(BEFORE)'!I7), "%", ""), ",", ".")), 0)) -> 0 | K7: =IFERROR(H7*I7,0) -> 29595.4 | L7: {=_xlfn.LET( _xlpm.valuta, UPPER(TRIM('Sales_RAW(BEFORE)'!K7)), _xlfn.IFS( _xlpm.valuta = "", "", OR(_xlpm.valuta = "USD", _xlpm.valuta = "$"), "$", OR(_xlpm.valuta = "EUR", _xlpm.valuta = "€"), "€", TRUE, _xlpm.valuta ) )} -> $ | M7: ="E" & TEXT(VALUE(SUBSTITUTE(SUBSTITUTE(SUBSTITUTE(UPPER(TRIM('Sales_RAW(BEFORE)'!L7)), "EMP", ""), "E", ""), "-", "")),"000") -> E022 | N7: =_xlfn.XLOOKUP(M7,Employees!$D$2:$D$26,Employees!$A$2:$A$26) -> Chris Williams | O7: =_xlfn.XLOOKUP(N7,Employees!$A$2:$A$26,Employees!$C$2:$C$26,2) -> Sales | P7: =PROPER('Sales_RAW(BEFORE)'!N7) -> South | Q7: =VLOOKUP(N7,Employees!$A$2:$B$26,2,FALSE) -> Boston | R7: =PROPER('Sales_RAW(BEFORE)'!P7) -> Umbrella Inc | S7: =SUBSTITUTE(SUBSTITUTE('Sales_RAW(BEFORE)'!Q7,"EIN",""),":","") -> 943040526 | T7: emma.company.com | U7: 949.620.8386 | V7: 771 Williams Ave | W7: null | X7: USA | Y7: =PROPER('Sales_RAW(BEFORE)'!W7) -> Credit Card | Z7: =PROPER('Sales_RAW(BEFORE)'!X7) -> Cancelled | AA7: {=_xlfn.LET( _xlpm.val, TRIM(LOWER('Sales_RAW(BEFORE)'!Y7)), _xlfn.IFS( OR(_xlpm.val="yes", _xlpm.val="paid"), "Paid", OR(_xlpm.val="no", _xlpm.val="unpaid"), "Unpaid", OR(_xlpm.val="partial", _xlpm.val="partial paid"), "Partial", _xlpm.val="", "", TRUE, 'Sales_RAW(BEFORE)'!AY7 ) )} -> Partial | AB7: INV/2026/0003 | AC7: =PROPER('Sales_RAW(BEFORE)'!AA7) -> Store | AD7: =SUBSTITUTE(SUBSTITUTE(SUBSTITUTE(SUBSTITUTE('Sales_RAW(BEFORE)'!AB7,"st",""),"q",""),"Q",""),"uarter","") -> 1 | AE7: =TEXT(IFERROR(DATEVALUE('Sales_RAW(BEFORE)'!AC7 & " 1"), IFERROR(DATE(2025, 'Sales_RAW(BEFORE)'!AC7, 1), 'Sales_RAW(BEFORE)'!AC7)), "mmmm") -> April | AF7: =_xlfn.LET( _xlpm.raw, TRIM(SUBSTITUTE('Sales_RAW(BEFORE)'!AD7, "'", "")), _xlpm.num, IFERROR(VALUE(_xlpm.raw), 0), IF(_xlpm.num < 100, 2000 + _xlpm.num, _xlpm.num) ) -> 2026 | AG7: =PROPER('Sales_RAW(BEFORE)'!AE7) -> Net 60 | AH7: {=_xlfn.LET( _xlpm.val, LOWER(TRIM('Sales_RAW(BEFORE)'!AF7)), _xlfn.IFS( OR(_xlpm.val="", _xlpm.val="null", _xlpm.val="N/A", _xlpm.val="-", _xlpm.val="#N/A"), 0, ISNUMBER('Sales_RAW(BEFORE)'!AF7), 'Sales_RAW(BEFORE)'!AF7, TRUE, IFERROR(_xlfn.NUMBERVALUE(_xlpm.val), 0) ) )} -> 51 | AI7: =IF(IFERROR(VALUE(SUBSTITUTE(SUBSTITUTE(TRIM('Sales_RAW(BEFORE)'!AG7), "%", ""), ",", ".")), 0) > 1, IFERROR(VALUE(SUBSTITUTE(SUBSTITUTE(TRIM('Sales_RAW(BEFORE)'!AG7), "%", ""), ",", ".")), 0) / 100, IFERROR(VALUE(SUBSTITUTE(SUBSTITUTE(TRIM('Sales_RAW(BEFORE)'!AG7), "%", ""), ",", ".")), 0)) -> 0.08 | AJ7: =K7*AI7 -> 2367.632 | AK7: =AJ7+K7 -> 31963.032 | AL7: =IFERROR(VALUE(SUBSTITUTE(SUBSTITUTE(SUBSTITUTE('Sales_RAW(BEFORE)'!AJ7,"$",""),"USD",""),",",".")),0) -> 24.16 | AM7: =SUBSTITUTE(SUBSTITUTE(PROPER('Sales_RAW(BEFORE)'!AK7), "Fed Ex", "FedEx"),"Fedex","FedEx") -> FedEx | AN7: DH273577842 | AO7: =SUBSTITUTE('Sales_RAW(BEFORE)'!AM7,"kg","") -> 24,37 | AP7: =_xlfn.LET( _xlpm.raw, UPPER(TRIM('Sales_RAW(BEFORE)'!AN7)), _xlpm.clean, RIGHT(_xlpm.raw, 1), IF(OR(_xlpm.raw="", _xlpm.raw="null"), "N/A", _xlpm.clean) ) -> A | AQ7: 231 | AV7: =IF(IFERROR(VALUE(SUBSTITUTE(SUBSTITUTE(TRIM('Sales_RAW(BEFORE)'!AT7), "%", ""), ",", ".")), 0) > 1, IFERROR(VALUE(SUBSTITUTE(SUBSTITUTE(TRIM('Sales_RAW(BEFORE)'!AT7), "%", ""), ",", ".")), 0) / 100, IFERROR(VALUE(SUBSTITUTE(SUBSTITUTE(TRIM('Sales_RAW(BEFORE)'!AT7), "%", ""), ",", ".")), 0)) -> 0.18 | AW7: =BA7*(_xlfn.XLOOKUP(N7,Employees!$A$2:$A$26,Employees!$E$2:$E$26,2)) -> 815.05732 | AX7: =PROPER('Sales_RAW(BEFORE)'!AV7) -> Emma Williams | AY7: =AX7 -> Emma Williams | AZ7: VIP customer | BA7: =AK7*(1-(_xlfn.XLOOKUP(G7, Exchange_Rates!$B$8:$F$8, Exchange_Rates!$B$9:$F$9, 0)+J7)) -> 27168.577 | BB7: {=_xlfn.LET( _xlpm.raw_dt, SUBSTITUTE(TRIM(C7), ".", "/"), _xlpm.dt, IFERROR(DATEVALUE(_xlpm.raw_dt), C7), _xlpm.p_code, TRIM(E7), _xlpm.w_text, LOWER(_xlfn.XLOOKUP(_xlpm.p_code, Product_List!$B$2:$B$61, Product_List!$F$2:$F$61, "24")), _xlpm.m_count, _xlfn.IFS( ISNUMBER(SEARCH("36", _xlpm.w_text)), 36, ISNUMBER(SEARCH("3 yr", _xlpm.w_text)), 36, ISNUMBER(SEARCH("12", _xlpm.w_text)), 12, ISNUMBER(SEARCH("1 yr", _xlpm.w_text)), 12, TRUE, 24 ), IFERROR(EDATE(_xlpm.dt, _xlpm.m_count), "Proveri datum") )} -> 47221 | BC7: =BA7*AV7 -> 4890.3439
A8: TR-2025004 | B8: 46050 | C8: 46144 | D8: ="P-" & TEXT(VALUE(SUBSTITUTE(SUBSTITUTE(SUBSTITUTE(UPPER(TRIM('Sales_RAW(BEFORE)'!D8)), "P", ""), "-", ""), "_", "")),"000") -> P-048 | E8: =VLOOKUP(D8,Product_List!$A$2:$B$61,2,FALSE) -> License Plus 48 | F8: =_xlfn.XLOOKUP(E8,Product_List!$B$2:$B$61,Product_List!$E$2:$E$61,2) -> BestParts | G8: =VLOOKUP(E8,Product_List!$B$2:$C$61,2,FALSE) -> Software | H8: =SUBSTITUTE(SUBSTITUTE('Sales_RAW(BEFORE)'!G8,"kom",""),".","") -> 34 | I8: =VLOOKUP(E8,Product_List!$B$2:$D$61,3,FALSE) -> 471.22 | J8: =IF(IFERROR(VALUE(SUBSTITUTE(SUBSTITUTE(TRIM('Sales_RAW(BEFORE)'!I8), "%", ""), ",", ".")), 0) > 1, IFERROR(VALUE(SUBSTITUTE(SUBSTITUTE(TRIM('Sales_RAW(BEFORE)'!I8), "%", ""), ",", ".")), 0) / 100, IFERROR(VALUE(SUBSTITUTE(SUBSTITUTE(TRIM('Sales_RAW(BEFORE)'!I8), "%", ""), ",", ".")), 0)) -> 0.05 | K8: =IFERROR(H8*I8,0) -> 16021.48 | L8: {=_xlfn.LET( _xlpm.valuta, UPPER(TRIM('Sales_RAW(BEFORE)'!K8)), _xlfn.IFS( _xlpm.valuta = "", "", OR(_xlpm.valuta = "USD", _xlpm.valuta = "$"), "$", OR(_xlpm.valuta = "EUR", _xlpm.valuta = "€"), "€", TRUE, _xlpm.valuta ) )} -> $ | M8: ="E" & TEXT(VALUE(SUBSTITUTE(SUBSTITUTE(SUBSTITUTE(UPPER(TRIM('Sales_RAW(BEFORE)'!L8)), "EMP", ""), "E", ""), "-", "")),"000") -> E014 | N8: =_xlfn.XLOOKUP(M8,Employees!$D$2:$D$26,Employees!$A$2:$A$26) -> Sophia Brown | O8: =_xlfn.XLOOKUP(N8,Employees!$A$2:$A$26,Employees!$C$2:$C$26,2) -> Online | P8: =PROPER('Sales_RAW(BEFORE)'!N8) -> West | Q8: =VLOOKUP(N8,Employees!$A$2:$B$26,2,FALSE) -> New York | R8: =PROPER('Sales_RAW(BEFORE)'!P8) -> Initech Inc | S8: =SUBSTITUTE(SUBSTITUTE('Sales_RAW(BEFORE)'!Q8,"EIN",""),":","") -> 986261507 | T8: sarah.gmail.com | U8: (240) 201-3058 | V8: 642 Jones Blvd | W8: 92564 | X8: USA | Y8: =PROPER('Sales_RAW(BEFORE)'!W8) -> Credit Card | Z8: =PROPER('Sales_RAW(BEFORE)'!X8) -> Processing | AA8: {=_xlfn.LET( _xlpm.val, TRIM(LOWER('Sales_RAW(BEFORE)'!Y8)), _xlfn.IFS( OR(_xlpm.val="yes", _xlpm.val="paid"), "Paid", OR(_xlpm.val="no", _xlpm.val="unpaid"), "Unpaid", OR(_xlpm.val="partial", _xlpm.val="partial paid"), "Partial", _xlpm.val="", "", TRUE, 'Sales_RAW(BEFORE)'!AY8 ) )} -> Paid | AB8: INV/2026/0004 | AC8: =PROPER('Sales_RAW(BEFORE)'!AA8) -> Online | AD8: =SUBSTITUTE(SUBSTITUTE(SUBSTITUTE(SUBSTITUTE('Sales_RAW(BEFORE)'!AB8,"st",""),"q",""),"Q",""),"uarter","") -> 1 | AE8: =TEXT(IFERROR(DATEVALUE('Sales_RAW(BEFORE)'!AC8 & " 1"), IFERROR(DATE(2025, 'Sales_RAW(BEFORE)'!AC8, 1), 'Sales_RAW(BEFORE)'!AC8)), "mmmm") -> January | AF8: =_xlfn.LET( _xlpm.raw, TRIM(SUBSTITUTE('Sales_RAW(BEFORE)'!AD8, "'", "")), _xlpm.num, IFERROR(VALUE(_xlpm.raw), 0), IF(_xlpm.num < 100, 2000 + _xlpm.num, _xlpm.num) ) -> 2026 | AG8: =PROPER('Sales_RAW(BEFORE)'!AE8) -> 15 | AH8: {=_xlfn.LET( _xlpm.val, LOWER(TRIM('Sales_RAW(BEFORE)'!AF8)), _xlfn.IFS( OR(_xlpm.val="", _xlpm.val="null", _xlpm.val="N/A", _xlpm.val="-", _xlpm.val="#N/A"), 0, ISNUMBER('Sales_RAW(BEFORE)'!AF8), 'Sales_RAW(BEFORE)'!AF8, TRUE, IFERROR(_xlfn.NUMBERVALUE(_xlpm.val), 0) ) )} -> 0 | AI8: =IF(IFERROR(VALUE(SUBSTITUTE(SUBSTITUTE(TRIM('Sales_RAW(BEFORE)'!AG8), "%", ""), ",", ".")), 0) > 1, IFERROR(VALUE(SUBSTITUTE(SUBSTITUTE(TRIM('Sales_RAW(BEFORE)'!AG8), "%", ""), ",", ".")), 0) / 100, IFERROR(VALUE(SUBSTITUTE(SUBSTITUTE(TRIM('Sales_RAW(BEFORE)'!AG8), "%", ""), ",", ".")), 0)) -> 0.08 | AJ8: =K8*AI8 -> 1281.7184 | AK8: =AJ8+K8 -> 17303.198 | AL8: =IFERROR(VALUE(SUBSTITUTE(SUBSTITUTE(SUBSTITUTE('Sales_RAW(BEFORE)'!AJ8,"$",""),"USD",""),",",".")),0) -> 49.82 | AM8: =SUBSTITUTE(SUBSTITUTE(PROPER('Sales_RAW(BEFORE)'!AK8), "Fed Ex", "FedEx"),"Fedex","FedEx") -> Usps | AN8: 1Z610354022 | AO8: =SUBSTITUTE('Sales_RAW(BEFORE)'!AM8,"kg","") -> 16.5 | AP8: =_xlfn.LET( _xlpm.raw, UPPER(TRIM('Sales_RAW(BEFORE)'!AN8)), _xlpm.clean, RIGHT(_xlpm.raw, 1), IF(OR(_xlpm.raw="", _xlpm.raw="null"), "N/A", _xlpm.clean) ) -> B | AQ8: 0 | AR8: {=_xlfn.LET( _xlpm.raw, LOWER(TRIM('Sales_RAW(BEFORE)'!AP8)), _xlfn.IFS( OR(_xlpm.raw="", _xlpm.raw="null"), "", _xlpm.raw="excellent", 5, _xlpm.raw="good", 4, _xlpm.raw="average", 3, _xlpm.raw="poor", 2, _xlpm.raw="terrible", 1, ISNUMBER(SEARCH("/", _xlpm.raw)), _xlfn.NUMBERVALUE(_xlfn.TEXTBEFORE(_xlpm.raw, "/")), TRUE, IFERROR(_xlfn.NUMBERVALUE(_xlpm.raw), "") ) )} -> 5 | AS8: satisfied | AV8: =IF(IFERROR(VALUE(SUBSTITUTE(SUBSTITUTE(TRIM('Sales_RAW(BEFORE)'!AT8), "%", ""), ",", ".")), 0) > 1, IFERROR(VALUE(SUBSTITUTE(SUBSTITUTE(TRIM('Sales_RAW(BEFORE)'!AT8), "%", ""), ",", ".")), 0) / 100, IFERROR(VALUE(SUBSTITUTE(SUBSTITUTE(TRIM('Sales_RAW(BEFORE)'!AT8), "%", ""), ",", ".")), 0)) -> 0 | AW8: =BA8*(_xlfn.XLOOKUP(N8,Employees!$A$2:$A$26,Employees!$E$2:$E$26,2)) -> 415.27676 | AX8: =PROPER('Sales_RAW(BEFORE)'!AV8) -> Sarah Davis | AY8: =AX8 -> Sarah Davis | AZ8: Check price | BA8: =AK8*(1-(_xlfn.XLOOKUP(G8, Exchange_Rates!$B$8:$F$8, Exchange_Rates!$B$9:$F$9, 0)+J8)) -> 13842.559 | BB8: {=_xlfn.LET( _xlpm.raw_dt, SUBSTITUTE(TRIM(C8), ".", "/"), _xlpm.dt, IFERROR(DATEVALUE(_xlpm.raw_dt), C8), _xlpm.p_code, TRIM(E8), _xlpm.w_text, LOWER(_xlfn.XLOOKUP(_xlpm.p_code, Product_List!$B$2:$B$61, Product_List!$F$2:$F$61, "24")), _xlpm.m_count, _xlfn.IFS( ISNUMBER(SEARCH("36", _xlpm.w_text)), 36, ISNUMBER(SEARCH("3 yr", _xlpm.w_text)), 36, ISNUMBER(SEARCH("12", _xlpm.w_text)), 12, ISNUMBER(SEARCH("1 yr", _xlpm.w_text)), 12, TRUE, 24 ), IFERROR(EDATE(_xlpm.dt, _xlpm.m_count), "Proveri datum") )} -> 46509 | BC8: =BA8*AV8 -> 0
A9: TR-2025005 | B9: 46174 | C9: 46271 | D9: ="P-" & TEXT(VALUE(SUBSTITUTE(SUBSTITUTE(SUBSTITUTE(UPPER(TRIM('Sales_RAW(BEFORE)'!D9)), "P", ""), "-", ""), "_", "")),"000") -> P-001 | E9: =VLOOKUP(D9,Product_List!$A$2:$B$61,2,FALSE) -> Desk X 1 | F9: =_xlfn.XLOOKUP(E9,Product_List!$B$2:$B$61,Product_List!$E$2:$E$61,2) -> Global Distrib | G9: =VLOOKUP(E9,Product_List!$B$2:$C$61,2,FALSE) -> Software | H9: =SUBSTITUTE(SUBSTITUTE('Sales_RAW(BEFORE)'!G9,"kom",""),".","") -> 14 | I9: =VLOOKUP(E9,Product_List!$B$2:$D$61,3,FALSE) -> 978.15 | J9: =IF(IFERROR(VALUE(SUBSTITUTE(SUBSTITUTE(TRIM('Sales_RAW(BEFORE)'!I9), "%", ""), ",", ".")), 0) > 1, IFERROR(VALUE(SUBSTITUTE(SUBSTITUTE(TRIM('Sales_RAW(BEFORE)'!I9), "%", ""), ",", ".")), 0) / 100, IFERROR(VALUE(SUBSTITUTE(SUBSTITUTE(TRIM('Sales_RAW(BEFORE)'!I9), "%", ""), ",", ".")), 0)) -> 0.1 | K9: =IFERROR(H9*I9,0) -> 13694.1 | L9: {=_xlfn.LET( _xlpm.valuta, UPPER(TRIM('Sales_RAW(BEFORE)'!K9)), _xlfn.IFS( _xlpm.valuta = "", "", OR(_xlpm.valuta = "USD", _xlpm.valuta = "$"), "$", OR(_xlpm.valuta = "EUR", _xlpm.valuta = "€"), "€", TRUE, _xlpm.valuta ) )} -> $ | M9: ="E" & TEXT(VALUE(SUBSTITUTE(SUBSTITUTE(SUBSTITUTE(UPPER(TRIM('Sales_RAW(BEFORE)'!L9)), "EMP", ""), "E", ""), "-", "")),"000") -> E010 | N9: =_xlfn.XLOOKUP(M9,Employees!$D$2:$D$26,Employees!$A$2:$A$26) -> Olivia Anderson | O9: =_xlfn.XLOOKUP(N9,Employees!$A$2:$A$26,Employees!$C$2:$C$26,2) -> Online | P9: =PROPER('Sales_RAW(BEFORE)'!N9) -> South | Q9: =VLOOKUP(N9,Employees!$A$2:$B$26,2,FALSE) -> Houston | R9: =PROPER('Sales_RAW(BEFORE)'!P9) -> Initech Inc | S9: =SUBSTITUTE(SUBSTITUTE('Sales_RAW(BEFORE)'!Q9,"EIN",""),":","") -> 134245587 | T9: laura.company.com | U9: +1 373 311 1047 | V9: 431 Johnson St. | W9: 50824 | X9: USA | Y9: =PROPER('Sales_RAW(BEFORE)'!W9) -> Wire Transfer | Z9: =PROPER('Sales_RAW(BEFORE)'!X9) -> Delivered | AA9: {=_xlfn.LET( _xlpm.val, TRIM(LOWER('Sales_RAW(BEFORE)'!Y9)), _xlfn.IFS( OR(_xlpm.val="yes", _xlpm.val="paid"), "Paid", OR(_xlpm.val="no", _xlpm.val="unpaid"), "Unpaid", OR(_xlpm.val="partial", _xlpm.val="partial paid"), "Partial", _xlpm.val="", "", TRUE, 'Sales_RAW(BEFORE)'!AY9 ) )} -> Paid | AB9: INV/2026/0005 | AC9: =PROPER('Sales_RAW(BEFORE)'!AA9) -> Phone | AD9: =SUBSTITUTE(SUBSTITUTE(SUBSTITUTE(SUBSTITUTE('Sales_RAW(BEFORE)'!AB9,"st",""),"q",""),"Q",""),"uarter","") -> 1 | AE9: =TEXT(IFERROR(DATEVALUE('Sales_RAW(BEFORE)'!AC9 & " 1"), IFERROR(DATE(2025, 'Sales_RAW(BEFORE)'!AC9, 1), 'Sales_RAW(BEFORE)'!AC9)), "mmmm") -> June | AF9: =_xlfn.LET( _xlpm.raw, TRIM(SUBSTITUTE('Sales_RAW(BEFORE)'!AD9, "'", "")), _xlpm.num, IFERROR(VALUE(_xlpm.raw), 0), IF(_xlpm.num < 100, 2000 + _xlpm.num, _xlpm.num) ) -> 2026 | AG9: =PROPER('Sales_RAW(BEFORE)'!AE9) -> Immediate | AH9: {=_xlfn.LET( _xlpm.val, LOWER(TRIM('Sales_RAW(BEFORE)'!AF9)), _xlfn.IFS( OR(_xlpm.val="", _xlpm.val="null", _xlpm.val="N/A", _xlpm.val="-", _xlpm.val="#N/A"), 0, ISNUMBER('Sales_RAW(BEFORE)'!AF9), 'Sales_RAW(BEFORE)'!AF9, TRUE, IFERROR(_xlfn.NUMBERVALUE(_xlpm.val), 0) ) )} -> 24 | AI9: =IF(IFERROR(VALUE(SUBSTITUTE(SUBSTITUTE(TRIM('Sales_RAW(BEFORE)'!AG9), "%", ""), ",", ".")), 0) > 1, IFERROR(VALUE(SUBSTITUTE(SUBSTITUTE(TRIM('Sales_RAW(BEFORE)'!AG9), "%", ""), ",", ".")), 0) / 100, IFERROR(VALUE(SUBSTITUTE(SUBSTITUTE(TRIM('Sales_RAW(BEFORE)'!AG9), "%", ""), ",", ".")), 0)) -> 0.08 | AJ9: =K9*AI9 -> 1095.528 | AK9: =AJ9+K9 -> 14789.628 | AL9: =IFERROR(VALUE(SUBSTITUTE(SUBSTITUTE(SUBSTITUTE('Sales_RAW(BEFORE)'!AJ9,"$",""),"USD",""),",",".")),0) -> 2 | AM9: =SUBSTITUTE(SUBSTITUTE(PROPER('Sales_RAW(BEFORE)'!AK9), "Fed Ex", "FedEx"),"Fedex","FedEx") -> Usps | AN9: FX143647055 | AO9: =SUBSTITUTE('Sales_RAW(BEFORE)'!AM9,"kg","") -> 11.33 | AP9: =_xlfn.LET( _xlpm.raw, UPPER(TRIM('Sales_RAW(BEFORE)'!AN9)), _xlpm.clean, RIGHT(_xlpm.raw, 1), IF(OR(_xlpm.raw="", _xlpm.raw="null"), "N/A", _xlpm.clean) ) -> B | AQ9: 99 | AR9: {=_xlfn.LET( _xlpm.raw, LOWER(TRIM('Sales_RAW(BEFORE)'!AP9)), _xlfn.IFS( OR(_xlpm.raw="", _xlpm.raw="null"), "", _xlpm.raw="excellent", 5, _xlpm.raw="good", 4, _xlpm.raw="average", 3, _xlpm.raw="poor", 2, _xlpm.raw="terrible", 1, ISNUMBER(SEARCH("/", _xlpm.raw)), _xlfn.NUMBERVALUE(_xlfn.TEXTBEFORE(_xlpm.raw, "/")), TRUE, IFERROR(_xlfn.NUMBERVALUE(_xlpm.raw), "") ) )} -> 5 | AV9: =IF(IFERROR(VALUE(SUBSTITUTE(SUBSTITUTE(TRIM('Sales_RAW(BEFORE)'!AT9), "%", ""), ",", ".")), 0) > 1, IFERROR(VALUE(SUBSTITUTE(SUBSTITUTE(TRIM('Sales_RAW(BEFORE)'!AT9), "%", ""), ",", ".")), 0) / 100, IFERROR(VALUE(SUBSTITUTE(SUBSTITUTE(TRIM('Sales_RAW(BEFORE)'!AT9), "%", ""), ",", ".")), 0)) -> 0.15 | AW9: =BA9*(_xlfn.XLOOKUP(N9,Employees!$A$2:$A$26,Employees!$E$2:$E$26,2)) -> 332.76663 | AX9: =PROPER('Sales_RAW(BEFORE)'!AV9) -> Laura Brown | AY9: =AX9 -> Laura Brown | BA9: =AK9*(1-(_xlfn.XLOOKUP(G9, Exchange_Rates!$B$8:$F$8, Exchange_Rates!$B$9:$F$9, 0)+J9)) -> 11092.221 | BB9: {=_xlfn.LET( _xlpm.raw_dt, SUBSTITUTE(TRIM(C9), ".", "/"), _xlpm.dt, IFERROR(DATEVALUE(_xlpm.raw_dt), C9), _xlpm.p_code, TRIM(E9), _xlpm.w_text, LOWER(_xlfn.XLOOKUP(_xlpm.p_code, Product_List!$B$2:$B$61, Product_List!$F$2:$F$61, "24")), _xlpm.m_count, _xlfn.IFS( ISNUMBER(SEARCH("36", _xlpm.w_text)), 36, ISNUMBER(SEARCH("3 yr", _xlpm.w_text)), 36, ISNUMBER(SEARCH("12", _xlpm.w_text)), 12, ISNUMBER(SEARCH("1 yr", _xlpm.w_text)), 12, TRUE, 24 ), IFERROR(EDATE(_xlpm.dt, _xlpm.m_count), "Proveri datum") )} -> 47002 | BC9: =BA9*AV9 -> 1663.8332
